
#==============================================================================
# START!!! 401_credit_pivot.py    PID: 2472    time: 2018-06-16 02:27:36.327157
#==============================================================================

  0%|          | 0/20 [00:00<?, ?it/s]  5%|▌         | 1/20 [00:00<00:10,  1.76it/s] 10%|█         | 2/20 [00:00<00:08,  2.11it/s] 15%|█▌        | 3/20 [00:01<00:07,  2.43it/s] 20%|██        | 4/20 [00:01<00:06,  2.54it/s] 25%|██▌       | 5/20 [00:02<00:06,  2.34it/s] 30%|███       | 6/20 [00:02<00:05,  2.48it/s] 35%|███▌      | 7/20 [00:02<00:05,  2.55it/s] 40%|████      | 8/20 [00:03<00:04,  2.60it/s] 45%|████▌     | 9/20 [00:03<00:04,  2.52it/s] 50%|█████     | 10/20 [00:03<00:03,  2.57it/s] 55%|█████▌    | 11/20 [00:04<00:03,  2.61it/s] 60%|██████    | 12/20 [00:04<00:03,  2.56it/s] 65%|██████▌   | 13/20 [00:05<00:02,  2.59it/s] 70%|███████   | 14/20 [00:05<00:02,  2.63it/s] 75%|███████▌  | 15/20 [00:05<00:01,  2.60it/s] 80%|████████  | 16/20 [00:06<00:01,  2.65it/s] 85%|████████▌ | 17/20 [00:06<00:01,  2.62it/s] 90%|█████████ | 18/20 [00:06<00:00,  2.64it/s] 95%|█████████▌| 19/20 [00:07<00:00,  2.66it/s]100%|██████████| 20/20 [00:07<00:00,  2.64it/s]
  0%|          | 0/20 [00:00<?, ?it/s] 25%|██▌       | 5/20 [00:00<00:00, 47.93it/s] 50%|█████     | 10/20 [00:00<00:00, 44.65it/s] 75%|███████▌  | 15/20 [00:00<00:00, 43.86it/s]100%|██████████| 20/20 [00:00<00:00, 43.75it/s]
  0%|          | 0/20 [00:00<?, ?it/s]100%|██████████| 20/20 [00:00<00:00, 252.62it/s]
Traceback (most recent call last):
  File "/home/kazuki_onodera/anaconda3/lib/python3.6/site-packages/pandas/core/indexes/base.py", line 2525, in get_loc
    return self._engine.get_loc(key)
  File "pandas/_libs/index.pyx", line 117, in pandas._libs.index.IndexEngine.get_loc
  File "pandas/_libs/index.pyx", line 139, in pandas._libs.index.IndexEngine.get_loc
  File "pandas/_libs/hashtable_class_helper.pxi", line 1265, in pandas._libs.hashtable.PyObjectHashTable.get_item
  File "pandas/_libs/hashtable_class_helper.pxi", line 1273, in pandas._libs.hashtable.PyObjectHashTable.get_item
KeyError: 'SK_ID_CURR'

During handling of the above exception, another exception occurred:

Traceback (most recent call last):
  File "401_credit_pivot.py", line 46, in <module>
    cre_ = utils.merge(cre_, col_app)
  File "/home/kazuki_onodera/Home-Credit-Default-Risk/py/utils.py", line 308, in merge
    df_ = pd.merge(df, trte, on='SK_ID_CURR', how='left')
  File "/home/kazuki_onodera/anaconda3/lib/python3.6/site-packages/pandas/core/reshape/merge.py", line 57, in merge
    validate=validate)
  File "/home/kazuki_onodera/anaconda3/lib/python3.6/site-packages/pandas/core/reshape/merge.py", line 565, in __init__
    self.join_names) = self._get_merge_keys()
  File "/home/kazuki_onodera/anaconda3/lib/python3.6/site-packages/pandas/core/reshape/merge.py", line 824, in _get_merge_keys
    right_keys.append(right[rk]._values)
  File "/home/kazuki_onodera/anaconda3/lib/python3.6/site-packages/pandas/core/frame.py", line 2139, in __getitem__
    return self._getitem_column(key)
  File "/home/kazuki_onodera/anaconda3/lib/python3.6/site-packages/pandas/core/frame.py", line 2146, in _getitem_column
    return self._get_item_cache(key)
  File "/home/kazuki_onodera/anaconda3/lib/python3.6/site-packages/pandas/core/generic.py", line 1842, in _get_item_cache
    values = self._data.get(item)
  File "/home/kazuki_onodera/anaconda3/lib/python3.6/site-packages/pandas/core/internals.py", line 3843, in get
    loc = self.items.get_loc(item)
  File "/home/kazuki_onodera/anaconda3/lib/python3.6/site-packages/pandas/core/indexes/base.py", line 2527, in get_loc
    return self._engine.get_loc(self._maybe_cast_indexer(key))
  File "pandas/_libs/index.pyx", line 117, in pandas._libs.index.IndexEngine.get_loc
  File "pandas/_libs/index.pyx", line 139, in pandas._libs.index.IndexEngine.get_loc
  File "pandas/_libs/hashtable_class_helper.pxi", line 1265, in pandas._libs.hashtable.PyObjectHashTable.get_item
  File "pandas/_libs/hashtable_class_helper.pxi", line 1273, in pandas._libs.hashtable.PyObjectHashTable.get_item
KeyError: 'SK_ID_CURR'
